Workbook

Sheet Estoque
A1: Código | B1: Nome do item | C1: Unidade | D1: Estoque inicial | E1: Quantidade atual | F1: Estoque mínimo | G1: Status
A2: 01-001 | B2: Microbrush | C2: Tubos | D2: 20 | E2: =IF(A2="","",D2+SUMIFS('Movimentações'!$E$2:$E1000,'Movimentações'!$C$2:$C1000,A2,'Movimentações'!$B$2:$B1000,"Entrada")-SUMIFS('Movimentações'!$E$2:$E1000,'Movimentações'!$C$2:$C1000,A2,'Movimentações'!$B$2:$B1000,"Saída")) -> 20 | F2: 5 | G2: =IF(A2="","",IF(E2<F2,"🔴 REPOR",IF(E2=F2,"🟡 ATENÇÃO","🟢 NORMAL"))) -> 🟢 NORMAL
A3: 01-002 | B3: Adesivo Universal | C3: Tubos | D3: 3 | E3: =IF(A3="","",D3+SUMIFS('Movimentações'!$E$2:$E1000,'Movimentações'!$C$2:$C1000,A3,'Movimentações'!$B$2:$B1000,"Entrada")-SUMIFS('Movimentações'!$E$2:$E1000,'Movimentações'!$C$2:$C1000,A3,'Movimentações'!$B$2:$B1000,"Saída")) -> 3 | F3: 2 | G3: =IF(A3="","",IF(E3<F3,"🔴 REPOR",IF(E3=F3,"🟡 ATENÇÃO","🟢 NORMAL"))) -> 🟢 NORMAL
A4: 01-003 | B4: Ácido Fosfórico 37% | C4: Tubos | D4: 1 | E4: =IF(A4="","",D4+SUMIFS('Movimentações'!$E$2:$E1000,'Movimentações'!$C$2:$C1000,A4,'Movimentações'!$B$2:$B1000,"Entrada")-SUMIFS('Movimentações'!$E$2:$E1000,'Movimentações'!$C$2:$C1000,A4,'Movimentações'!$B$2:$B1000,"Saída")) -> 0 | F4: 8 | G4: =IF(A4="","",IF(E4<F4,"🔴 REPOR",IF(E4=F4,"🟡 ATENÇÃO","🟢 NORMAL"))) -> 🔴 REPOR
A5: 01-004 | B5: Ionômero de Vidro | C5: Frasco | D5: 3 | E5: =IF(A5="","",D5+SUMIFS('Movimentações'!$E$2:$E1000,'Movimentações'!$C$2:$C1000,A5,'Movimentações'!$B$2:$B1000,"Entrada")-SUMIFS('Movimentações'!$E$2:$E1000,'Movimentações'!$C$2:$C1000,A5,'Movimentações'!$B$2:$B1000,"Saída")) -> 3 | F5: 4 | G5: =IF(A5="","",IF(E5<F5,"🔴 REPOR",IF(E5=F5,"🟡 ATENÇÃO","🟢 NORMAL"))) -> 🔴 REPOR
A6: 01-005 | B6: Benzotop | C6: Frasco | D6: 4 | E6: =IF(A6="","",D6+SUMIFS('Movimentações'!$E$2:$E1000,'Movimentações'!$C$2:$C1000,A6,'Movimentações'!$B$2:$B1000,"Entrada")-SUMIFS('Movimentações'!$E$2:$E1000,'Movimentações'!$C$2:$C1000,A6,'Movimentações'!$B$2:$B1000,"Saída")) -> 4 | F6: 2 | G6: =IF(A6="","",IF(E6<F6,"🔴 REPOR",IF(E6=F6,"🟡 ATENÇÃO","🟢 NORMAL"))) -> 🟢 NORMAL
A7: 01-006 | B7: Cimento reparador MTA (2 aplicações) | C7: Frasco | D7: 2 | E7: =IF(A7="","",D7+SUMIFS('Movimentações'!$E$2:$E1000,'Movimentações'!$C$2:$C1000,A7,'Movimentações'!$B$2:$B1000,"Entrada")-SUMIFS('Movimentações'!$E$2:$E1000,'Movimentações'!$C$2:$C1000,A7,'Movimentações'!$B$2:$B1000,"Saída")) -> 2 | F7: 2 | G7: =IF(A7="","",IF(E7<F7,"🔴 REPOR",IF(E7=F7,"🟡 ATENÇÃO","🟢 NORMAL"))) -> 🟡 ATENÇÃO
A8: 01-007 | B8: Cimento de hidróxido de cálcio (Dentística) | C8: Frasco | D8: 3 | E8: =IF(A8="","",D8+SUMIFS('Movimentações'!$E$2:$E1000,'Movimentações'!$C$2:$C1000,A8,'Movimentações'!$B$2:$B1000,"Entrada")-SUMIFS('Movimentações'!$E$2:$E1000,'Movimentações'!$C$2:$C1000,A8,'Movimentações'!$B$2:$B1000,"Saída")) -> 3 | F8: 2 | G8: =IF(A8="","",IF(E8<F8,"🔴 REPOR",IF(E8=F8,"🟡 ATENÇÃO","🟢 NORMAL"))) -> 🟢 NORMAL
A9: 01-008 | B9: Banda matriz aço 7 mm | C9: Unidade | D9: 13 | E9: =IF(A9="","",D9+SUMIFS('Movimentações'!$E$2:$E1000,'Movimentações'!$C$2:$C1000,A9,'Movimentações'!$B$2:$B1000,"Entrada")-SUMIFS('Movimentações'!$E$2:$E1000,'Movimentações'!$C$2:$C1000,A9,'Movimentações'!$B$2:$B1000,"Saída")) -> 13 | F9: 6 | G9: =IF(A9="","",IF(E9<F9,"🔴 REPOR",IF(E9=F9,"🟡 ATENÇÃO","🟢 NORMAL"))) -> 🟢 NORMAL
A10: 01-009 | B10: Banda matriz aço 5 mm | C10: Unidade | D10: 26 | E10: =IF(A10="","",D10+SUMIFS('Movimentações'!$E$2:$E1000,'Movimentações'!$C$2:$C1000,A10,'Movimentações'!$B$2:$B1000,"Entrada")-SUMIFS('Movimentações'!$E$2:$E1000,'Movimentações'!$C$2:$C1000,A10,'Movimentações'!$B$2:$B1000,"Saída")) -> 26 | F10: 6 | G10: =IF(A10="","",IF(E10<F10,"🔴 REPOR",IF(E10=F10,"🟡 ATENÇÃO","🟢 NORMAL"))) -> 🟢 NORMAL
A11: 01-010 | B11: Inter-A (material restaurador intermediário) | C11: Frasco | D11: 1 | E11: =IF(A11="","",D11+SUMIFS('Movimentações'!$E$2:$E1000,'Movimentações'!$C$2:$C1000,A11,'Movimentações'!$B$2:$B1000,"Entrada")-SUMIFS('Movimentações'!$E$2:$E1000,'Movimentações'!$C$2:$C1000,A11,'Movimentações'!$B$2:$B1000,"Saída")) -> 1 | F11: 2 | G11: =IF(A11="","",IF(E11<F11,"🔴 REPOR",IF(E11=F11,"🟡 ATENÇÃO","🟢 NORMAL"))) -> 🔴 REPOR
A12: 01-011 | B12: Coroa Hable adulto | C12: Pacote | D12: 1 | E12: =IF(A12="","",D12+SUMIFS('Movimentações'!$E$2:$E1000,'Movimentações'!$C$2:$C1000,A12,'Movimentações'!$B$2:$B1000,"Entrada")-SUMIFS('Movimentações'!$E$2:$E1000,'Movimentações'!$C$2:$C1000,A12,'Movimentações'!$B$2:$B1000,"Saída")) -> 1 | F12: 1 | G12: =IF(A12="","",IF(E12<F12,"🔴 REPOR",IF(E12=F12,"🟡 ATENÇÃO","🟢 NORMAL"))) -> 🟡 ATENÇÃO
A13: 01-012 | B13: Coroa Hable pediátrica | C13: Pacote | D13: 1 | E13: =IF(A13="","",D13+SUMIFS('Movimentações'!$E$2:$E1000,'Movimentações'!$C$2:$C1000,A13,'Movimentações'!$B$2:$B1000,"Entrada")-SUMIFS('Movimentações'!$E$2:$E1000,'Movimentações'!$C$2:$C1000,A13,'Movimentações'!$B$2:$B1000,"Saída")) -> 1 | F13: 1 | G13: =IF(A13="","",IF(E13<F13,"🔴 REPOR",IF(E13=F13,"🟡 ATENÇÃO","🟢 NORMAL"))) -> 🟡 ATENÇÃO
A14: 01-013 | B14: Resina composta A1E | C14: Unidade | D14: 2 | E14: =IF(A14="","",D14+SUMIFS('Movimentações'!$E$2:$E1000,'Movimentações'!$C$2:$C1000,A14,'Movimentações'!$B$2:$B1000,"Entrada")-SUMIFS('Movimentações'!$E$2:$E1000,'Movimentações'!$C$2:$C1000,A14,'Movimentações'!$B$2:$B1000,"Saída")) -> 2 | F14: 1 | G14: =IF(A14="","",IF(E14<F14,"🔴 REPOR",IF(E14=F14,"🟡 ATENÇÃO","🟢 NORMAL"))) -> 🟢 NORMAL
A15: 01-014 | B15: Resina composta A2E | C15: Unidade | D15: 2 | E15: =IF(A15="","",D15+SUMIFS('Movimentações'!$E$2:$E1000,'Movimentações'!$C$2:$C1000,A15,'Movimentações'!$B$2:$B1000,"Entrada")-SUMIFS('Movimentações'!$E$2:$E1000,'Movimentações'!$C$2:$C1000,A15,'Movimentações'!$B$2:$B1000,"Saída")) -> 2 | F15: 2 | G15: =IF(A15="","",IF(E15<F15,"🔴 REPOR",IF(E15=F15,"🟡 ATENÇÃO","🟢 NORMAL"))) -> 🟡 ATENÇÃO
A16: 01-015 | B16: Resina composta A3E | C16: Unidade | D16: 1 | E16: =IF(A16="","",D16+SUMIFS('Movimentações'!$E$2:$E1000,'Movimentações'!$C$2:$C1000,A16,'Movimentações'!$B$2:$B1000,"Entrada")-SUMIFS('Movimentações'!$E$2:$E1000,'Movimentações'!$C$2:$C1000,A16,'Movimentações'!$B$2:$B1000,"Saída")) -> 1 | F16: 4 | G16: =IF(A16="","",IF(E16<F16,"🔴 REPOR",IF(E16=F16,"🟡 ATENÇÃO","🟢 NORMAL"))) -> 🔴 REPOR
A17: 01-016 | B17: Resina composta A1B | C17: Unidade | D17: 1 | E17: =IF(A17="","",D17+SUMIFS('Movimentações'!$E$2:$E1000,'Movimentações'!$C$2:$C1000,A17,'Movimentações'!$B$2:$B1000,"Entrada")-SUMIFS('Movimentações'!$E$2:$E1000,'Movimentações'!$C$2:$C1000,A17,'Movimentações'!$B$2:$B1000,"Saída")) -> 1 | F17: 1 | G17: =IF(A17="","",IF(E17<F17,"🔴 REPOR",IF(E17=F17,"🟡 ATENÇÃO","🟢 NORMAL"))) -> 🟡 ATENÇÃO
A18: 01-017 | B18: Resina composta A2B | C18: Unidade | D18: 0 | E18: =IF(A18="","",D18+SUMIFS('Movimentações'!$E$2:$E1000,'Movimentações'!$C$2:$C1000,A18,'Movimentações'!$B$2:$B1000,"Entrada")-SUMIFS('Movimentações'!$E$2:$E1000,'Movimentações'!$C$2:$C1000,A18,'Movimentações'!$B$2:$B1000,"Saída")) -> 0 | F18: 2 | G18: =IF(A18="","",IF(E18<F18,"🔴 REPOR",IF(E18=F18,"🟡 ATENÇÃO","🟢 NORMAL"))) -> 🔴 REPOR
A19: 01-018 | B19: Resina composta A3B | C19: Unidade | D19: 0 | E19: =IF(A19="","",D19+SUMIFS('Movimentações'!$E$2:$E1000,'Movimentações'!$C$2:$C1000,A19,'Movimentações'!$B$2:$B1000,"Entrada")-SUMIFS('Movimentações'!$E$2:$E1000,'Movimentações'!$C$2:$C1000,A19,'Movimentações'!$B$2:$B1000,"Saída")) -> 0 | F19: 4 | G19: =IF(A19="","",IF(E19<F19,"🔴 REPOR",IF(E19=F19,"🟡 ATENÇÃO","🟢 NORMAL"))) -> 🔴 REPOR
A20: 01-019 | B20: Resina composta A3.5B | C20: Unidade | D20: 0 | E20: =IF(A20="","",D20+SUMIFS('Movimentações'!$E$2:$E1000,'Movimentações'!$C$2:$C1000,A20,'Movimentações'!$B$2:$B1000,"Entrada")-SUMIFS('Movimentações'!$E$2:$E1000,'Movimentações'!$C$2:$C1000,A20,'Movimentações'!$B$2:$B1000,"Saída")) -> 0 | F20: 4 | G20: =IF(A20="","",IF(E20<F20,"🔴 REPOR",IF(E20=F20,"🟡 ATENÇÃO","🟢 NORMAL"))) -> 🔴 REPOR
A21: 01-020 | B21: Forrador Dentinário Liner | C21: Unidade | D21: 0 | E21: =IF(A21="","",D21+SUMIFS('Movimentações'!$E$2:$E1000,'Movimentações'!$C$2:$C1000,A21,'Movimentações'!$B$2:$B1000,"Entrada")-SUMIFS('Movimentações'!$E$2:$E1000,'Movimentações'!$C$2:$C1000,A21,'Movimentações'!$B$2:$B1000,"Saída")) -> 0 | F21: 2 | G21: =IF(A21="","",IF(E21<F21,"🔴 REPOR",IF(E21=F21,"🟡 ATENÇÃO","🟢 NORMAL"))) -> 🔴 REPOR
A22: 01-021 | B22: Discos de lixa P/M/G com mandril | C22: Pacote | D22: 5 | E22: =IF(A22="","",D22+SUMIFS('Movimentações'!$E$2:$E1000,'Movimentações'!$C$2:$C1000,A22,'Movimentações'!$B$2:$B1000,"Entrada")-SUMIFS('Movimentações'!$E$2:$E1000,'Movimentações'!$C$2:$C1000,A22,'Movimentações'!$B$2:$B1000,"Saída")) -> 5 | F22: 2 | G22: =IF(A22="","",IF(E22<F22,"🔴 REPOR",IF(E22=F22,"🟡 ATENÇÃO","🟢 NORMAL"))) -> 🟢 NORMAL
A23: 01-022 | B23: Disco de lixa M com mandril | C23: Pacote | D23: 1 | E23: =IF(A23="","",D23+SUMIFS('Movimentações'!$E$2:$E1000,'Movimentações'!$C$2:$C1000,A23,'Movimentações'!$B$2:$B1000,"Entrada")-SUMIFS('Movimentações'!$E$2:$E1000,'Movimentações'!$C$2:$C1000,A23,'Movimentações'!$B$2:$B1000,"Saída")) -> 1 | F23: 2 | G23: =IF(A23="","",IF(E23<F23,"🔴 REPOR",IF(E23=F23,"🟡 ATENÇÃO","🟢 NORMAL"))) -> 🔴 REPOR
A24: 01-023 | B24: Bloco de papel p/ espatulação | C24: Bloco | D24: 3 | E24: =IF(A24="","",D24+SUMIFS('Movimentações'!$E$2:$E1000,'Movimentações'!$C$2:$C1000,A24,'Movimentações'!$B$2:$B1000,"Entrada")-SUMIFS('Movimentações'!$E$2:$E1000,'Movimentações'!$C$2:$C1000,A24,'Movimentações'!$B$2:$B1000,"Saída")) -> 3 | F24: 4 | G24: =IF(A24="","",IF(E24<F24,"🔴 REPOR",IF(E24=F24,"🟡 ATENÇÃO","🟢 NORMAL"))) -> 🔴 REPOR
A25: 01-024 | B25: Arco Young plástico | C25: Unidade | D25: 2 | E25: =IF(A25="","",D25+SUMIFS('Movimentações'!$E$2:$E1000,'Movimentações'!$C$2:$C1000,A25,'Movimentações'!$B$2:$B1000,"Entrada")-SUMIFS('Movimentações'!$E$2:$E1000,'Movimentações'!$C$2:$C1000,A25,'Movimentações'!$B$2:$B1000,"Saída")) -> 2 | F25: 2 | G25: =IF(A25="","",IF(E25<F25,"🔴 REPOR",IF(E25=F25,"🟡 ATENÇÃO","🟢 NORMAL"))) -> 🟡 ATENÇÃO
A26: 01-025 | B26: Fio dental | C26: Unidade | D26: 9 | E26: =IF(A26="","",D26+SUMIFS('Movimentações'!$E$2:$E1000,'Movimentações'!$C$2:$C1000,A26,'Movimentações'!$B$2:$B1000,"Entrada")-SUMIFS('Movimentações'!$E$2:$E1000,'Movimentações'!$C$2:$C1000,A26,'Movimentações'!$B$2:$B1000,"Saída")) -> 9 | F26: 6 | G26: =IF(A26="","",IF(E26<F26,"🔴 REPOR",IF(E26=F26,"🟡 ATENÇÃO","🟢 NORMAL"))) -> 🟢 NORMAL
A27: 01-026 | B27: Disco de lixa superfino s/ mandril | C27: Pacote | D27: 7 | E27: =IF(A27="","",D27+SUMIFS('Movimentações'!$E$2:$E1000,'Movimentações'!$C$2:$C1000,A27,'Movimentações'!$B$2:$B1000,"Entrada")-SUMIFS('Movimentações'!$E$2:$E1000,'Movimentações'!$C$2:$C1000,A27,'Movimentações'!$B$2:$B1000,"Saída")) -> 7 | F27: 4 | G27: =IF(A27="","",IF(E27<F27,"🔴 REPOR",IF(E27=F27,"🟡 ATENÇÃO","🟢 NORMAL"))) -> 🟢 NORMAL
A28: 01-027 | B28: Disco de lixa grosso s/ mandril | C28: Pacote | D28: 4 | E28: =IF(A28="","",D28+SUMIFS('Movimentações'!$E$2:$E1000,'Movimentações'!$C$2:$C1000,A28,'Movimentações'!$B$2:$B1000,"Entrada")-SUMIFS('Movimentações'!$E$2:$E1000,'Movimentações'!$C$2:$C1000,A28,'Movimentações'!$B$2:$B1000,"Saída")) -> 4 | F28: 4 | G28: =IF(A28="","",IF(E28<F28,"🔴 REPOR",IF(E28=F28,"🟡 ATENÇÃO","🟢 NORMAL"))) -> 🟡 ATENÇÃO
A29: 01-028 | B29: Tira de poliéster p/ acabamento | C29: Pacote | D29: 14 | E29: =IF(A29="","",D29+SUMIFS('Movimentações'!$E$2:$E1000,'Movimentações'!$C$2:$C1000,A29,'Movimentações'!$B$2:$B1000,"Entrada")-SUMIFS('Movimentações'!$E$2:$E1000,'Movimentações'!$C$2:$C1000,A29,'Movimentações'!$B$2:$B1000,"Saída")) -> 14 | F29: 4 | G29: =IF(A29="","",IF(E29<F29,"🔴 REPOR",IF(E29=F29,"🟡 ATENÇÃO","🟢 NORMAL"))) -> 🟢 NORMAL
A30: 01-029 | B30: Tira de poliéster transparente | C30: Pacote | D30: 15 | E30: =IF(A30="","",D30+SUMIFS('Movimentações'!$E$2:$E1000,'Movimentações'!$C$2:$C1000,A30,'Movimentações'!$B$2:$B1000,"Entrada")-SUMIFS('Movimentações'!$E$2:$E1000,'Movimentações'!$C$2:$C1000,A30,'Movimentações'!$B$2:$B1000,"Saída")) -> 15 | F30: 4 | G30: =IF(A30="","",IF(E30<F30,"🔴 REPOR",IF(E30=F30,"🟡 ATENÇÃO","🟢 NORMAL"))) -> 🟢 NORMAL
A31: 01-030 | B31: Cunha de madeira | C31: Pacote | D31: 7 | E31: =IF(A31="","",D31+SUMIFS('Movimentações'!$E$2:$E1000,'Movimentações'!$C$2:$C1000,A31,'Movimentações'!$B$2:$B1000,"Entrada")-SUMIFS('Movimentações'!$E$2:$E1000,'Movimentações'!$C$2:$C1000,A31,'Movimentações'!$B$2:$B1000,"Saída")) -> 7 | F31: 4 | G31: =IF(A31="","",IF(E31<F31,"🔴 REPOR",IF(E31=F31,"🟡 ATENÇÃO","🟢 NORMAL"))) -> 🟢 NORMAL
A32: 01-031 | B32: Papel carbono | C32: Pacote | D32: 70 | E32: =IF(A32="","",D32+SUMIFS('Movimentações'!$E$2:$E1000,'Movimentações'!$C$2:$C1000,A32,'Movimentações'!$B$2:$B1000,"Entrada")-SUMIFS('Movimentações'!$E$2:$E1000,'Movimentações'!$C$2:$C1000,A32,'Movimentações'!$B$2:$B1000,"Saída")) -> 70 | F32: 8 | G32: =IF(A32="","",IF(E32<F32,"🔴 REPOR",IF(E32=F32,"🟡 ATENÇÃO","🟢 NORMAL"))) -> 🟢 NORMAL
A33: 01-032 | B33: Fio retrator | C33: Unidade | D33: 2 | E33: =IF(A33="","",D33+SUMIFS('Movimentações'!$E$2:$E1000,'Movimentações'!$C$2:$C1000,A33,'Movimentações'!$B$2:$B1000,"Entrada")-SUMIFS('Movimentações'!$E$2:$E1000,'Movimentações'!$C$2:$C1000,A33,'Movimentações'!$B$2:$B1000,"Saída")) -> 2 | F33: 2 | G33: =IF(A33="","",IF(E33<F33,"🔴 REPOR",IF(E33=F33,"🟡 ATENÇÃO","🟢 NORMAL"))) -> 🟡 ATENÇÃO
A34: 02-001 | B34: Esponja Hemostática | C34: Pacote | D34: 1 | E34: =IF(A34="","",D34+SUMIFS('Movimentações'!$E$2:$E1000,'Movimentações'!$C$2:$C1000,A34,'Movimentações'!$B$2:$B1000,"Entrada")-SUMIFS('Movimentações'!$E$2:$E1000,'Movimentações'!$C$2:$C1000,A34,'Movimentações'!$B$2:$B1000,"Saída")) -> 1 | F34: 2 | G34: =IF(A34="","",IF(E34<F34,"🔴 REPOR",IF(E34=F34,"🟡 ATENÇÃO","🟢 NORMAL"))) -> 🔴 REPOR
A35: 02-002 | B35: Líquido Hemostático | C35: Frasco | D35: 1 | E35: =IF(A35="","",D35+SUMIFS('Movimentações'!$E$2:$E1000,'Movimentações'!$C$2:$C1000,A35,'Movimentações'!$B$2:$B1000,"Entrada")-SUMIFS('Movimentações'!$E$2:$E1000,'Movimentações'!$C$2:$C1000,A35,'Movimentações'!$B$2:$B1000,"Saída")) -> 1 | F35: 2 | G35: =IF(A35="","",IF(E35<F35,"🔴 REPOR",IF(E35=F35,"🟡 ATENÇÃO","🟢 NORMAL"))) -> 🔴 REPOR
A36: 02-003 | B36: Lâmina de bisturi | C36: Caixa | D36: 2 | E36: =IF(A36="","",D36+SUMIFS('Movimentações'!$E$2:$E1000,'Movimentações'!$C$2:$C1000,A36,'Movimentações'!$B$2:$B1000,"Entrada")-SUMIFS('Movimentações'!$E$2:$E1000,'Movimentações'!$C$2:$C1000,A36,'Movimentações'!$B$2:$B1000,"Saída")) -> 2 | F36: 2 | G36: =IF(A36="","",IF(E36<F36,"🔴 REPOR",IF(E36=F36,"🟡 ATENÇÃO","🟢 NORMAL"))) -> 🟡 ATENÇÃO
A37: 02-004 | B37: Agulha 22 G (preta) | C37: Caixa | D37: 6 | E37: =IF(A37="","",D37+SUMIFS('Movimentações'!$E$2:$E1000,'Movimentações'!$C$2:$C1000,A37,'Movimentações'!$B$2:$B1000,"Entrada")-SUMIFS('Movimentações'!$E$2:$E1000,'Movimentações'!$C$2:$C1000,A37,'Movimentações'!$B$2:$B1000,"Saída")) -> 6 | F37: 2 | G37: =IF(A37="","",IF(E37<F37,"🔴 REPOR",IF(E37=F37,"🟡 ATENÇÃO","🟢 NORMAL"))) -> 🟢 NORMAL
A38: 02-005 | B38: Fio de sutura | C38: Caixa | D38: 4 | E38: =IF(A38="","",D38+SUMIFS('Movimentações'!$E$2:$E1000,'Movimentações'!$C$2:$C1000,A38,'Movimentações'!$B$2:$B1000,"Entrada")-SUMIFS('Movimentações'!$E$2:$E1000,'Movimentações'!$C$2:$C1000,A38,'Movimentações'!$B$2:$B1000,"Saída")) -> 4 | F38: 2 | G38: =IF(A38="","",IF(E38<F38,"🔴 REPOR",IF(E38=F38,"🟡 ATENÇÃO","🟢 NORMAL"))) -> 🟢 NORMAL
A39: 03-001 | B39: Bicarbonato de sódio | C39: Caixa | D39: 9 | E39: =IF(A39="","",D39+SUMIFS('Movimentações'!$E$2:$E1000,'Movimentações'!$C$2:$C1000,A39,'Movimentações'!$B$2:$B1000,"Entrada")-SUMIFS('Movimentações'!$E$2:$E1000,'Movimentações'!$C$2:$C1000,A39,'Movimentações'!$B$2:$B1000,"Saída")) -> 9 | F39: 2 | G39: =IF(A39="","",IF(E39<F39,"🔴 REPOR",IF(E39=F39,"🟡 ATENÇÃO","🟢 NORMAL"))) -> 🟢 NORMAL
A40: 04-001 | B40: NDP | C40: Caixa | D40: 1 | E40: =IF(A40="","",D40+SUMIFS('Movimentações'!$E$2:$E1000,'Movimentações'!$C$2:$C1000,A40,'Movimentações'!$B$2:$B1000,"Entrada")-SUMIFS('Movimentações'!$E$2:$E1000,'Movimentações'!$C$2:$C1000,A40,'Movimentações'!$B$2:$B1000,"Saída")) -> 1 | F40: 2 | G40: =IF(A40="","",IF(E40<F40,"🔴 REPOR",IF(E40=F40,"🟡 ATENÇÃO","🟢 NORMAL"))) -> 🔴 REPOR
...

Sheet Movimentações
A1: Data | B1: Tipo | C1: Código | D1: Item | E1: Quantidade | F1: Observação
A2: 46246 | B2: Saída | C2: 01-003 | D2: {=IF(C2="","",IFERROR(_xlfn.XLOOKUP(C2,Estoque!$A:$A,Estoque!$B:$B,""),""))} -> Ácido Fosfórico 37% | E2: 1
A3: 46259 | B3: Saída | C3: 05-009 | D3: {=IF(C3="","",IFERROR(_xlfn.XLOOKUP(C3,Estoque!$A:$A,Estoque!$B:$B,""),""))} -> Avental de TNT | E3: 2
A4: 46259 | B4: Saída | C4: 05-026 | D4: {=IF(C4="","",IFERROR(_xlfn.XLOOKUP(C4,Estoque!$A:$A,Estoque!$B:$B,""),""))} -> Gaze | E4: 2
A5: 46259 | B5: Saída | C5: 05-023 | D5: {=IF(C5="","",IFERROR(_xlfn.XLOOKUP(C5,Estoque!$A:$A,Estoque!$B:$B,""),""))} -> Guardanapo | E5: 2
A6: 46259 | B6: Saída | C6: 05-024 | D6: {=IF(C6="","",IFERROR(_xlfn.XLOOKUP(C6,Estoque!$A:$A,Estoque!$B:$B,""),""))} -> Água destilada | E6: 1
A7: 46259 | B7: Saída | C7: 05-017 | D7: {=IF(C7="","",IFERROR(_xlfn.XLOOKUP(C7,Estoque!$A:$A,Estoque!$B:$B,""),""))} -> Álcool 70% | E7: 1
A8: 46259 | B8: Saída | C8: 05-025 | D8: {=IF(C8="","",IFERROR(_xlfn.XLOOKUP(C8,Estoque!$A:$A,Estoque!$B:$B,""),""))} -> Babador | E8: 1
D9: {=IF(C9="","",IFERROR(_xlfn.XLOOKUP(C9,Estoque!$A:$A,Estoque!$B:$B,""),""))}
D10: {=IF(C10="","",IFERROR(_xlfn.XLOOKUP(C10,Estoque!$A:$A,Estoque!$B:$B,""),""))}
D11: {=IF(C11="","",IFERROR(_xlfn.XLOOKUP(C11,Estoque!$A:$A,Estoque!$B:$B,""),""))}
D12: {=IF(C12="","",IFERROR(_xlfn.XLOOKUP(C12,Estoque!$A:$A,Estoque!$B:$B,""),""))}
D13: {=IF(C13="","",IFERROR(_xlfn.XLOOKUP(C13,Estoque!$A:$A,Estoque!$B:$B,""),""))}
D14: {=IF(C14="","",IFERROR(_xlfn.XLOOKUP(C14,Estoque!$A:$A,Estoque!$B:$B,""),""))}
D15: {=IF(C15="","",IFERROR(_xlfn.XLOOKUP(C15,Estoque!$A:$A,Estoque!$B:$B,""),""))}
D16: {=IF(C16="","",IFERROR(_xlfn.XLOOKUP(C16,Estoque!$A:$A,Estoque!$B:$B,""),""))}
D17: {=IF(C17="","",IFERROR(_xlfn.XLOOKUP(C17,Estoque!$A:$A,Estoque!$B:$B,""),""))}
D18: {=IF(C18="","",IFERROR(_xlfn.XLOOKUP(C18,Estoque!$A:$A,Estoque!$B:$B,""),""))}
D19: {=IF(C19="","",IFERROR(_xlfn.XLOOKUP(C19,Estoque!$A:$A,Estoque!$B:$B,""),""))}
D20: {=IF(C20="","",IFERROR(_xlfn.XLOOKUP(C20,Estoque!$A:$A,Estoque!$B:$B,""),""))}
... D1001: {=IF(C1001="","",IFERROR(_xlfn.XLOOKUP(C1001,Estoque!$A:$A,Estoque!$B:$B,""),""))}

Sheet Dashboard
A1: DASHBOARD DE ESTOQUE
A3: Total de itens | C3: 🟢 Estoque normal | E3: 🟡 Em atenção | G3: 🔴 Repor
A4: =COUNTIF(Estoque!A2:A501,"<>") -> 96 | C4: =COUNTIF(Estoque!G2:G501,"🟢 NORMAL") -> 57 | E4: =COUNTIF(Estoque!G2:G501,"🟡 ATENÇÃO") -> 12 | G4: =COUNTIF(Estoque!G2:G501,"🔴 REPOR") -> 27
A7: Status | B7: Quantidade
A8: Normal | B8: =COUNTIF(Estoque!G2:G501,"🟢 NORMAL") -> 57
A9: Atenção | B9: =COUNTIF(Estoque!G2:G501,"🟡 ATENÇÃO") -> 12
A10: Repor | B10: =COUNTIF(Estoque!G2:G501,"🔴 REPOR") -> 27
A13: Mês | B13: Entradas | C13: Saídas
A14: Jan | B14: =SUMIFS('Movimentações'!$E:$E,'Movimentações'!$B:$B,"Entrada",'Movimentações'!$A:$A,">="&DATE(YEAR(TODAY()),1,1),'Movimentações'!$A:$A,"<"&EDATE(DATE(YEAR(TODAY()),1,1),1)) -> 0 | C14: =SUMIFS('Movimentações'!$E:$E,'Movimentações'!$B:$B,"Saída",'Movimentações'!$A:$A,">="&DATE(YEAR(TODAY()),1,1),'Movimentações'!$A:$A,"<"&EDATE(DATE(YEAR(TODAY()),1,1),1)) -> 0
A15: Fev | B15: =SUMIFS('Movimentações'!$E:$E,'Movimentações'!$B:$B,"Entrada",'Movimentações'!$A:$A,">="&DATE(YEAR(TODAY()),2,1),'Movimentações'!$A:$A,"<"&EDATE(DATE(YEAR(TODAY()),2,1),1)) -> 0 | C15: =SUMIFS('Movimentações'!$E:$E,'Movimentações'!$B:$B,"Saída",'Movimentações'!$A:$A,">="&DATE(YEAR(TODAY()),2,1),'Movimentações'!$A:$A,"<"&EDATE(DATE(YEAR(TODAY()),2,1),1)) -> 0
A16: Mar | B16: =SUMIFS('Movimentações'!$E:$E,'Movimentações'!$B:$B,"Entrada",'Movimentações'!$A:$A,">="&DATE(YEAR(TODAY()),3,1),'Movimentações'!$A:$A,"<"&EDATE(DATE(YEAR(TODAY()),3,1),1)) -> 0 | C16: =SUMIFS('Movimentações'!$E:$E,'Movimentações'!$B:$B,"Saída",'Movimentações'!$A:$A,">="&DATE(YEAR(TODAY()),3,1),'Movimentações'!$A:$A,"<"&EDATE(DATE(YEAR(TODAY()),3,1),1)) -> 0
A17: Abr | B17: =SUMIFS('Movimentações'!$E:$E,'Movimentações'!$B:$B,"Entrada",'Movimentações'!$A:$A,">="&DATE(YEAR(TODAY()),4,1),'Movimentações'!$A:$A,"<"&EDATE(DATE(YEAR(TODAY()),4,1),1)) -> 0 | C17: =SUMIFS('Movimentações'!$E:$E,'Movimentações'!$B:$B,"Saída",'Movimentações'!$A:$A,">="&DATE(YEAR(TODAY()),4,1),'Movimentações'!$A:$A,"<"&EDATE(DATE(YEAR(TODAY()),4,1),1)) -> 0
A18: Mai | B18: =SUMIFS('Movimentações'!$E:$E,'Movimentações'!$B:$B,"Entrada",'Movimentações'!$A:$A,">="&DATE(YEAR(TODAY()),5,1),'Movimentações'!$A:$A,"<"&EDATE(DATE(YEAR(TODAY()),5,1),1)) -> 0 | C18: =SUMIFS('Movimentações'!$E:$E,'Movimentações'!$B:$B,"Saída",'Movimentações'!$A:$A,">="&DATE(YEAR(TODAY()),5,1),'Movimentações'!$A:$A,"<"&EDATE(DATE(YEAR(TODAY()),5,1),1)) -> 0
A19: Jun | B19: =SUMIFS('Movimentações'!$E:$E,'Movimentações'!$B:$B,"Entrada",'Movimentações'!$A:$A,">="&DATE(YEAR(TODAY()),6,1),'Movimentações'!$A:$A,"<"&EDATE(DATE(YEAR(TODAY()),6,1),1)) -> 0 | C19: =SUMIFS('Movimentações'!$E:$E,'Movimentações'!$B:$B,"Saída",'Movimentações'!$A:$A,">="&DATE(YEAR(TODAY()),6,1),'Movimentações'!$A:$A,"<"&EDATE(DATE(YEAR(TODAY()),6,1),1)) -> 0
A20: Jul | B20: =SUMIFS('Movimentações'!$E:$E,'Movimentações'!$B:$B,"Entrada",'Movimentações'!$A:$A,">="&DATE(YEAR(TODAY()),7,1),'Movimentações'!$A:$A,"<"&EDATE(DATE(YEAR(TODAY()),7,1),1)) -> 0 | C20: =SUMIFS('Movimentações'!$E:$E,'Movimentações'!$B:$B,"Saída",'Movimentações'!$A:$A,">="&DATE(YEAR(TODAY()),7,1),'Movimentações'!$A:$A,"<"&EDATE(DATE(YEAR(TODAY()),7,1),1)) -> 0
A21: Ago | B21: =SUMIFS('Movimentações'!$E:$E,'Movimentações'!$B:$B,"Entrada",'Movimentações'!$A:$A,">="&DATE(YEAR(TODAY()),8,1),'Movimentações'!$A:$A,"<"&EDATE(DATE(YEAR(TODAY()),8,1),1)) -> 0 | C21: =SUMIFS('Movimentações'!$E:$E,'Movimentações'!$B:$B,"Saída",'Movimentações'!$A:$A,">="&DATE(YEAR(TODAY()),8,1),'Movimentações'!$A:$A,"<"&EDATE(DATE(YEAR(TODAY()),8,1),1)) -> 10
A22: Set | B22: =SUMIFS('Movimentações'!$E:$E,'Movimentações'!$B:$B,"Entrada",'Movimentações'!$A:$A,">="&DATE(YEAR(TODAY()),9,1),'Movimentações'!$A:$A,"<"&EDATE(DATE(YEAR(TODAY()),9,1),1)) -> 0 | C22: =SUMIFS('Movimentações'!$E:$E,'Movimentações'!$B:$B,"Saída",'Movimentações'!$A:$A,">="&DATE(YEAR(TODAY()),9,1),'Movimentações'!$A:$A,"<"&EDATE(DATE(YEAR(TODAY()),9,1),1)) -> 0
A23: Out | B23: =SUMIFS('Movimentações'!$E:$E,'Movimentações'!$B:$B,"Entrada",'Movimentações'!$A:$A,">="&DATE(YEAR(TODAY()),10,1),'Movimentações'!$A:$A,"<"&EDATE(DATE(YEAR(TODAY()),10,1),1)) -> 0 | C23: =SUMIFS('Movimentações'!$E:$E,'Movimentações'!$B:$B,"Saída",'Movimentações'!$A:$A,">="&DATE(YEAR(TODAY()),10,1),'Movimentações'!$A:$A,"<"&EDATE(DATE(YEAR(TODAY()),10,1),1)) -> 0
A24: Nov | B24: =SUMIFS('Movimentações'!$E:$E,'Movimentações'!$B:$B,"Entrada",'Movimentações'!$A:$A,">="&DATE(YEAR(TODAY()),11,1),'Movimentações'!$A:$A,"<"&EDATE(DATE(YEAR(TODAY()),11,1),1)) -> 0 | C24: =SUMIFS('Movimentações'!$E:$E,'Movimentações'!$B:$B,"Saída",'Movimentações'!$A:$A,">="&DATE(YEAR(TODAY()),11,1),'Movimentações'!$A:$A,"<"&EDATE(DATE(YEAR(TODAY()),11,1),1)) -> 0
A25: Dez | B25: =SUMIFS('Movimentações'!$E:$E,'Movimentações'!$B:$B,"Entrada",'Movimentações'!$A:$A,">="&DATE(YEAR(TODAY()),12,1),'Movimentações'!$A:$A,"<"&EDATE(DATE(YEAR(TODAY()),12,1),1)) -> 0 | C25: =SUMIFS('Movimentações'!$E:$E,'Movimentações'!$B:$B,"Saída",'Movimentações'!$A:$A,">="&DATE(YEAR(TODAY()),12,1),'Movimentações'!$A:$A,"<"&EDATE(DATE(YEAR(TODAY()),12,1),1)) -> 0
A28: Itens que precisam de reposição
A29: Código | B29: Item | C29: Quantidade | D29: Mínimo | E29: Status
A30: =IFERROR(__xludf.DUMMYFUNCTION("IFERROR(FILTER({Estoque!A2:A501,Estoque!B2:B501,Estoque!E2:E501,Estoque!F2:F501,Estoque!G2:G501},(Estoque!G2:G501=""🔴 REPOR"")+(Estoque!G2:G501=""🟡 ATENÇÃO"")),""Nenhum item para reposição"")"),"01-003") -> 01-003 | B30: =IFERROR(__xludf.DUMMYFUNCTION("""COMPUTED_VALUE"""),"Ácido Fosfórico 37%") -> Ácido Fosfórico 37% | C30: =IFERROR(__xludf.DUMMYFUNCTION("""COMPUTED_VALUE"""),0.0) -> 0 | D30: =IFERROR(__xludf.DUMMYFUNCTION("""COMPUTED_VALUE"""),8.0) -> 8 | E30: =IFERROR(__xludf.DUMMYFUNCTION("""COMPUTED_VALUE"""),"🔴 REPOR") -> 🔴 REPOR
A31: =IFERROR(__xludf.DUMMYFUNCTION("""COMPUTED_VALUE"""),"01-004") -> 01-004 | B31: =IFERROR(__xludf.DUMMYFUNCTION("""COMPUTED_VALUE"""),"Ionômero de Vidro") -> Ionômero de Vidro | C31: =IFERROR(__xludf.DUMMYFUNCTION("""COMPUTED_VALUE"""),3.0) -> 3 | D31: =IFERROR(__xludf.DUMMYFUNCTION("""COMPUTED_VALUE"""),4.0) -> 4 | E31: =IFERROR(__xludf.DUMMYFUNCTION("""COMPUTED_VALUE"""),"🔴 REPOR") -> 🔴 REPOR
A32: =IFERROR(__xludf.DUMMYFUNCTION("""COMPUTED_VALUE"""),"01-006") -> 01-006 | B32: =IFERROR(__xludf.DUMMYFUNCTION("""COMPUTED_VALUE"""),"Cimento reparador MTA (2 aplicações)") -> Cimento reparador MTA (2 aplicações) | C32: =IFERROR(__xludf.DUMMYFUNCTION("""COMPUTED_VALUE"""),2.0) -> 2 | D32: =IFERROR(__xludf.DUMMYFUNCTION("""COMPUTED_VALUE"""),2.0) -> 2 | E32: =IFERROR(__xludf.DUMMYFUNCTION("""COMPUTED_VALUE"""),"🟡 ATENÇÃO") -> 🟡 ATENÇÃO
A33: =IFERROR(__xludf.DUMMYFUNCTION("""COMPUTED_VALUE"""),"01-010") -> 01-010 | B33: =IFERROR(__xludf.DUMMYFUNCTION("""COMPUTED_VALUE"""),"Inter-A (material restaurador intermediário)") -> Inter-A (material restaurador intermediário) | C33: =IFERROR(__xludf.DUMMYFUNCTION("""COMPUTED_VALUE"""),1.0) -> 1 | D33: =IFERROR(__xludf.DUMMYFUNCTION("""COMPUTED_VALUE"""),2.0) -> 2 | E33: =IFERROR(__xludf.DUMMYFUNCTION("""COMPUTED_VALUE"""),"🔴 REPOR") -> 🔴 REPOR
A34: =IFERROR(__xludf.DUMMYFUNCTION("""COMPUTED_VALUE"""),"01-011") -> 01-011 | B34: =IFERROR(__xludf.DUMMYFUNCTION("""COMPUTED_VALUE"""),"Coroa Hable adulto") -> Coroa Hable adulto | C34: =IFERROR(__xludf.DUMMYFUNCTION("""COMPUTED_VALUE"""),1.0) -> 1 | D34: =IFERROR(__xludf.DUMMYFUNCTION("""COMPUTED_VALUE"""),1.0) -> 1 | E34: =IFERROR(__xludf.DUMMYFUNCTION("""COMPUTED_VALUE"""),"🟡 ATENÇÃO") -> 🟡 ATENÇÃO
A35: =IFERROR(__xludf.DUMMYFUNCTION("""COMPUTED_VALUE"""),"01-012") -> 01-012 | B35: =IFERROR(__xludf.DUMMYFUNCTION("""COMPUTED_VALUE"""),"Coroa Hable pediátrica") -> Coroa Hable pediátrica | C35: =IFERROR(__xludf.DUMMYFUNCTION("""COMPUTED_VALUE"""),1.0) -> 1 | D35: =IFERROR(__xludf.DUMMYFUNCTION("""COMPUTED_VALUE"""),1.0) -> 1 | E35: =IFERROR(__xludf.DUMMYFUNCTION("""COMPUTED_VALUE"""),"🟡 ATENÇÃO") -> 🟡 ATENÇÃO
A36: =IFERROR(__xludf.DUMMYFUNCTION("""COMPUTED_VALUE"""),"01-014") -> 01-014 | B36: =IFERROR(__xludf.DUMMYFUNCTION("""COMPUTED_VALUE"""),"Resina composta A2E") -> Resina composta A2E | C36: =IFERROR(__xludf.DUMMYFUNCTION("""COMPUTED_VALUE"""),2.0) -> 2 | D36: =IFERROR(__xludf.DUMMYFUNCTION("""COMPUTED_VALUE"""),2.0) -> 2 | E36: =IFERROR(__xludf.DUMMYFUNCTION("""COMPUTED_VALUE"""),"🟡 ATENÇÃO") -> 🟡 ATENÇÃO
A37: =IFERROR(__xludf.DUMMYFUNCTION("""COMPUTED_VALUE"""),"01-015") -> 01-015 | B37: =IFERROR(__xludf.DUMMYFUNCTION("""COMPUTED_VALUE"""),"Resina composta A3E") -> Resina composta A3E | C37: =IFERROR(__xludf.DUMMYFUNCTION("""COMPUTED_VALUE"""),1.0) -> 1 | D37: =IFERROR(__xludf.DUMMYFUNCTION("""COMPUTED_VALUE"""),4.0) -> 4 | E37: =IFERROR(__xludf.DUMMYFUNCTION("""COMPUTED_VALUE"""),"🔴 REPOR") -> 🔴 REPOR
A38: =IFERROR(__xludf.DUMMYFUNCTION("""COMPUTED_VALUE"""),"01-016") -> 01-016 | B38: =IFERROR(__xludf.DUMMYFUNCTION("""COMPUTED_VALUE"""),"Resina composta A1B") -> Resina composta A1B | C38: =IFERROR(__xludf.DUMMYFUNCTION("""COMPUTED_VALUE"""),1.0) -> 1 | D38: =IFERROR(__xludf.DUMMYFUNCTION("""COMPUTED_VALUE"""),1.0) -> 1 | E38: =IFERROR(__xludf.DUMMYFUNCTION("""COMPUTED_VALUE"""),"🟡 ATENÇÃO") -> 🟡 ATENÇÃO
A39: =IFERROR(__xludf.DUMMYFUNCTION("""COMPUTED_VALUE"""),"01-017") -> 01-017 | B39: =IFERROR(__xludf.DUMMYFUNCTION("""COMPUTED_VALUE"""),"Resina composta A2B") -> Resina composta A2B | C39: =IFERROR(__xludf.DUMMYFUNCTION("""COMPUTED_VALUE"""),0.0) -> 0 | D39: =IFERROR(__xludf.DUMMYFUNCTION("""COMPUTED_VALUE"""),2.0) -> 2 | E39: =IFERROR(__xludf.DUMMYFUNCTION("""COMPUTED_VALUE"""),"🔴 REPOR") -> 🔴 REPOR
A40: =IFERROR(__xludf.DUMMYFUNCTION("""COMPUTED_VALUE"""),"01-018") -> 01-018 | B40: =IFERROR(__xludf.DUMMYFUNCTION("""COMPUTED_VALUE"""),"Resina composta A3B") -> Resina composta A3B | C40: =IFERROR(__xludf.DUMMYFUNCTION("""COMPUTED_VALUE"""),0.0) -> 0 | D40: =IFERROR(__xludf.DUMMYFUNCTION("""COMPUTED_VALUE"""),4.0) -> 4 | E40: =IFERROR(__xludf.DUMMYFUNCTION("""COMPUTED_VALUE"""),"🔴 REPOR") -> 🔴 REPOR
A41: =IFERROR(__xludf.DUMMYFUNCTION("""COMPUTED_VALUE"""),"01-019") -> 01-019 | B41: =IFERROR(__xludf.DUMMYFUNCTION("""COMPUTED_VALUE"""),"Resina composta A3.5B") -> Resina composta A3.5B | C41: =IFERROR(__xludf.DUMMYFUNCTION("""COMPUTED_VALUE"""),0.0) -> 0 | D41: =IFERROR(__xludf.DUMMYFUNCTION("""COMPUTED_VALUE"""),4.0) -> 4 | E41: =IFERROR(__xludf.DUMMYFUNCTION("""COMPUTED_VALUE"""),"🔴 REPOR") -> 🔴 REPOR
A42: =IFERROR(__xludf.DUMMYFUNCTION("""COMPUTED_VALUE"""),"01-020") -> 01-020 | B42: =IFERROR(__xludf.DUMMYFUNCTION("""COMPUTED_VALUE"""),"Forrador Dentinário Liner") -> Forrador Dentinário Liner | C42: =IFERROR(__xludf.DUMMYFUNCTION("""COMPUTED_VALUE"""),0.0) -> 0 | D42: =IFERROR(__xludf.DUMMYFUNCTION("""COMPUTED_VALUE"""),2.0) -> 2 | E42: =IFERROR(__xludf.DUMMYFUNCTION("""COMPUTED_VALUE"""),"🔴 REPOR") -> 🔴 REPOR
A43: =IFERROR(__xludf.DUMMYFUNCTION("""COMPUTED_VALUE"""),"01-022") -> 01-022 | B43: =IFERROR(__xludf.DUMMYFUNCTION("""COMPUTED_VALUE"""),"Disco de lixa M com mandril") -> Disco de lixa M com mandril | C43: =IFERROR(__xludf.DUMMYFUNCTION("""COMPUTED_VALUE"""),1.0) -> 1 | D43: =IFERROR(__xludf.DUMMYFUNCTION("""COMPUTED_VALUE"""),2.0) -> 2 | E43: =IFERROR(__xludf.DUMMYFUNCTION("""COMPUTED_VALUE"""),"🔴 REPOR") -> 🔴 REPOR
A44: =IFERROR(__xludf.DUMMYFUNCTION("""COMPUTED_VALUE"""),"01-023") -> 01-023 | B44: =IFERROR(__xludf.DUMMYFUNCTION("""COMPUTED_VALUE"""),"Bloco de papel p/ espatulação") -> Bloco de papel p/ espatulação | C44: =IFERROR(__xludf.DUMMYFUNCTION("""COMPUTED_VALUE"""),3.0) -> 3 | D44: =IFERROR(__xludf.DUMMYFUNCTION("""COMPUTED_VALUE"""),4.0) -> 4 | E44: =IFERROR(__xludf.DUMMYFUNCTION("""COMPUTED_VALUE"""),"🔴 REPOR") -> 🔴 REPOR
A45: =IFERROR(__xludf.DUMMYFUNCTION("""COMPUTED_VALUE"""),"01-024") -> 01-024 | B45: =IFERROR(__xludf.DUMMYFUNCTION("""COMPUTED_VALUE"""),"Arco Young plástico") -> Arco Young plástico | C45: =IFERROR(__xludf.DUMMYFUNCTION("""COMPUTED_VALUE"""),2.0) -> 2 | D45: =IFERROR(__xludf.DUMMYFUNCTION("""COMPUTED_VALUE"""),2.0) -> 2 | E45: =IFERROR(__xludf.DUMMYFUNCTION("""COMPUTED_VALUE"""),"🟡 ATENÇÃO") -> 🟡 ATENÇÃO
A46: =IFERROR(__xludf.DUMMYFUNCTION("""COMPUTED_VALUE"""),"01-027") -> 01-027 | B46: =IFERROR(__xludf.DUMMYFUNCTION("""COMPUTED_VALUE"""),"Disco de lixa grosso s/ mandril") -> Disco de lixa grosso s/ mandril | C46: =IFERROR(__xludf.DUMMYFUNCTION("""COMPUTED_VALUE"""),4.0) -> 4 | D46: =IFERROR(__xludf.DUMMYFUNCTION("""COMPUTED_VALUE"""),4.0) -> 4 | E46: =IFERROR(__xludf.DUMMYFUNCTION("""COMPUTED_VALUE"""),"🟡 ATENÇÃO") -> 🟡 ATENÇÃO
A47: =IFERROR(__xludf.DUMMYFUNCTION("""COMPUTED_VALUE"""),"01-032") -> 01-032 | B47: =IFERROR(__xludf.DUMMYFUNCTION("""COMPUTED_VALUE"""),"Fio retrator") -> Fio retrator | C47: =IFERROR(__xludf.DUMMYFUNCTION("""COMPUTED_VALUE"""),2.0) -> 2 | D47: =IFERROR(__xludf.DUMMYFUNCTION("""COMPUTED_VALUE"""),2.0) -> 2 | E47: =IFERROR(__xludf.DUMMYFUNCTION("""COMPUTED_VALUE"""),"🟡 ATENÇÃO") -> 🟡 ATENÇÃO
...

Sheet Listas
A1: Tipo de movimentação | B1: Unidade | C1: Códigos
A2: Entrada | B2: Unidade | C2: 1- Dentistica
A3: Saída | B3: Caixa | C3: 2- Cirurgia
B4: Pacote | C4: 3- Perio
B5: Litro | C5: 4- Endo
B6: Quilograma | C6: 5- Consumiveis
B7: Metro | C7: 6- Prótese
B8: Frasco | C8: 7- Instrumental
B9: Par
B10: Rolo
B11: Outro
